<?xml version="1.0" ?>
<!-- =================================================================================== -->
<!-- |    This document was autogenerated by xacro from sc.urdf                        | -->
<!-- |    EDITING THIS FILE BY HAND IS NOT RECOMMENDED                                 | -->
<!-- =================================================================================== -->
<!-- This URDF was automatically created by SolidWorks to URDF Exporter! Originally created by Stephen Brawner (brawner@gmail.com) 
     Commit Version: 1.6.0-4-g7f85cfe  Build Version: 1.6.7995.38578
     For more information, please see http://wiki.ros.org/sw_urdf_exporter -->
<robot name="sc">
  <link name="BASE">
    <inertial>
      <origin rpy="0 0 0" xyz="5.72467459547532E-09 0.0159202797459075 0.0194791934838799"/>
      <mass value="1"/>
      <inertia ixx="5" ixy="0" ixz="0" iyy="5" iyz="0" izz="5"/>
    </inertial>
    <visual>
      <origin rpy="0 0 0" xyz="0 0 0"/>
      <geometry>
        <mesh filename="package://sc_description/meshes/BASE.STL"/>
      </geometry>
      <material name="">
        <color rgba="1 1 1 1"/>
      </material>
    </visual>
    <collision>
      <origin rpy="0 0 0" xyz="0 0 0"/>
      <geometry>
        <mesh filename="package://sc_description/meshes/BASE.STL"/>
      </geometry>
    </collision>
  </link>
  <link name="Link1_1">
    <inertial>
      <origin rpy="0 0 0" xyz="-0.0305510790740942 0.0167741325759093 -0.0182493779419036"/>
      <mass value="0.2"/>
      <inertia ixx="5" ixy="0" ixz="0" iyy="5" iyz="0" izz="5"/>
    </inertial>
    <visual>
      <origin rpy="0 0 0" xyz="0 0 0"/>
      <geometry>
        <mesh filename="package://sc_description/meshes/Link1_1.STL"/>
      </geometry>
      
      <material name="">
        <color rgba="1 1 1 1"/>
      </material>
    </visual>
    <collision>
      <origin rpy="0 0 0" xyz="0 0 0"/>
      <geometry>
        <mesh filename="package://sc_description/meshes/Link1_1.STL"/>
      </geometry>
    </collision>
  </link>
  <joint name="Joint1_1" type="revolute">
    <origin rpy="0 0 0" xyz="-0.062392 0.061425 0.02595"/>
    <parent link="BASE"/>
    <child link="Link1_1"/>
    <axis xyz="0 0 1"/>
    <limit effort="100" lower="-7" upper="7" velocity="100"/>
  </joint>
  <link name="Link1_2">
    <inertial>
      <origin rpy="0 0 0" xyz="-0.0158388290918334 0.0300544158992501 0.0199694861387752"/>
      <mass value="0.2"/>
      <inertia ixx="5" ixy="0" ixz="0" iyy="5" iyz="0" izz="5"/>
    </inertial>
    <visual>
      <origin rpy="0 0 0" xyz="0 0 0"/>
      <geometry>
        <mesh filename="package://sc_description/meshes/Link1_2.STL"/>
      </geometry>
      <material name="">
        <color rgba="1 1 1 1"/>
      </material>
    </visual>
    <collision>
      <origin rpy="0 0 0" xyz="0 0 0"/>
      <geometry>
        <mesh filename="package://sc_description/meshes/Link1_2.STL"/>
      </geometry>
    </collision>
  </link>
  <joint name="Joint1_2" type="revolute">
    <origin rpy="0 0 0" xyz="-0.0480172012540558 0.00353176779071716 -0.0184000000000004"/>
    <parent link="Link1_1"/>
    <child link="Link1_2"/>
    <axis xyz="-0.499999999999997 -0.86602540378444 0"/>
    <limit effort="100" lower="-7" upper="7" velocity="100"/>
  </joint>
  <link name="Link1_3">
    <inertial>
      <origin rpy="0 0 0" xyz="0.016171988039484 0.0145112463016462 -0.0449869707899275"/>
      <mass value="0.2"/>
      <inertia ixx="5" ixy="0" ixz="0" iyy="5" iyz="0" izz="5"/>
    </inertial>
    <visual>
      <origin rpy="0 0 0" xyz="0 0 0"/>
      <geometry>
        <mesh filename="package://sc_description/meshes/Link1_3.STL"/>
      </geometry>
      <material name="">
        <color rgba="1 1 1 1"/>
      </material>
    </visual>
    <collision>
      <origin rpy="0 0 0" xyz="0 0 0"/>
      <geometry>
        <mesh filename="package://sc_description/meshes/Link1_3.STL"/>
        <friction>      
	    <ode>      
	       <mu>1.5</mu>
	       <mu2>1.5</mu2>
	    </ode>      
	  </friction>
      </geometry>
    </collision>
  </link>
  <joint name="Joint1_3" type="revolute">
    <origin rpy="0 0 0" xyz="-0.0497861313024054 0.0287440363093533 0.0399389722775644"/>
    <parent link="Link1_2"/>
    <child link="Link1_3"/>
    <axis xyz="-0.499999999999998 -0.86602540378444 0"/>
    <limit effort="100" lower="-7" upper="7" velocity="100"/>
  </joint>
  <link name="Link2_1">
    <inertial>
      <origin rpy="0 0 0" xyz="0.034845075167807 -0.000748713097714162 0.0182493777000012"/>
      <mass value="0.2"/>
      <inertia ixx="5" ixy="0" ixz="0" iyy="5" iyz="0" izz="5"/>
    </inertial>
    <visual>
      <origin rpy="0 0 0" xyz="0 0 0"/>
      <geometry>
        <mesh filename="package://sc_description/meshes/Link2_1.STL"/>
      </geometry>
      <material name="">
        <color rgba="1 1 1 1"/>
      </material>
    </visual>
    <collision>
      <origin rpy="0 0 0" xyz="0 0 0"/>
      <geometry>
        <mesh filename="package://sc_description/meshes/Link2_1.STL"/>
      </geometry>
    </collision>
  </link>
  <joint name="Joint2_1" type="revolute">
    <origin rpy="3.1416 0 3.1416" xyz="-0.082878 -0.0125 0.02595"/>
    <parent link="BASE"/>
    <child link="Link2_1"/>
    <axis xyz="0 0 -1"/>
    <limit effort="100" lower="-7" upper="7" velocity="100"/>
  </joint>
  <link name="Link2_2">
    <inertial>
      <origin rpy="0 0 0" xyz="-0.0287440363093526 0.018108473118737 0.0199694861387753"/>
      <mass value="0.2"/>
      <inertia ixx="5" ixy="0" ixz="0" iyy="5" iyz="0" izz="5"/>
    </inertial>
    <visual>
      <origin rpy="0 0 0" xyz="0 0 0"/>
      <geometry>
        <mesh filename="package://sc_description/meshes/Link2_2.STL"/>
      </geometry>
      <material name="">
        <color rgba="1 1 1 1"/>
      </material>
    </visual>
    <collision>
      <origin rpy="0 0 0" xyz="0 0 0"/>
      <geometry>
        <mesh filename="package://sc_description/meshes/Link2_2.STL"/>
      </geometry>
    </collision>
  </link>
  <joint name="Joint2_2" type="revolute">
    <origin rpy="3.14159265358979 0 3.14159265358979" xyz="0.0433500000000012 -0.0209499999999987 0.0184000000000004"/>
    <parent link="Link2_1"/>
    <child link="Link2_2"/>
    <axis xyz="0 -1 0"/>
    <limit effort="100" lower="-7" upper="7" velocity="100"/>
  </joint>
  <link name="Link2_3">
    <inertial>
      <origin rpy="0 0 0" xyz="0.00674972944168441 0.0206531015833406 -0.0449869694528496"/>
      <mass value="0.2"/>
      <inertia ixx="5" ixy="0" ixz="0" iyy="5" iyz="0" izz="5"/>
    </inertial>
    <visual>
      <origin rpy="0 0 0" xyz="0 0 0"/>
      <geometry>
        <mesh filename="package://sc_description/meshes/Link2_3.STL"/>
        
      </geometry>
      <material name="">
        <color rgba="1 1 1 1"/>
      </material>
    </visual>
    <collision>
      <origin rpy="0 0 0" xyz="0 0 0"/>
      <geometry>
        <mesh filename="package://sc_description/meshes/Link2_3.STL"/>
        <friction>      
	    <ode>      
	       <mu>1.5</mu>
	       <mu2>1.5</mu2>
	    </ode>      
	  </friction>
      </geometry>
    </collision>
  </link>
  <joint name="Joint2_3" type="revolute">
    <origin rpy="0 0 0" xyz="-0.0574880726187073 0 0.0399389722775644"/>
    <parent link="Link2_2"/>
    <child link="Link2_3"/>
    <axis xyz="0 -1 0"/>
    <limit effort="100" lower="-7" upper="7" velocity="100"/>
  </joint>
  <link name="Link3_1">
    <inertial>
      <origin rpy="0 0 0" xyz="-0.0298023675063099 -0.0180709386947381 -0.018249377359046"/>
      <mass value="0.2"/>
      <inertia ixx="5" ixy="0" ixz="0" iyy="5" iyz="0" izz="5"/>
    </inertial>
    <visual>
      <origin rpy="0 0 0" xyz="0 0 0"/>
      <geometry>
        <mesh filename="package://sc_description/meshes/Link3_1.STL"/>
      </geometry>
      <material name="">
        <color rgba="1 1 1 1"/>
      </material>
    </visual>
    <collision>
      <origin rpy="0 0 0" xyz="0 0 0"/>
      <geometry>
        <mesh filename="package://sc_description/meshes/Link3_1.STL"/>
      </geometry>
    </collision>
  </link>
  <joint name="Joint3_1" type="revolute">
    <origin rpy="0 0 0" xyz="-0.062392 -0.086425 0.02595"/>
    <parent link="BASE"/>
    <child link="Link3_1"/>
    <axis xyz="0 0 1"/>
    <limit effort="100" lower="-7" upper="7" velocity="100"/>
  </joint>
  <link name="Link3_2">
    <inertial>
      <origin rpy="0 0 0" xyz="-0.0339473022105701 0.00131037958989745 0.0199694861387753"/>
      <mass value="0.2"/>
      <inertia ixx="5" ixy="0" ixz="0" iyy="5" iyz="0" izz="5"/>
    </inertial>
    <visual>
      <origin rpy="0 0 0" xyz="0 0 0"/>
      <geometry>
        <mesh filename="package://sc_description/meshes/Link3_2.STL"/>
      </geometry>
      <material name="">
        <color rgba="1 1 1 1"/>
      </material>
    </visual>
    <collision>
      <origin rpy="0 0 0" xyz="0 0 0"/>
      <geometry>
        <mesh filename="package://sc_description/meshes/Link3_2.STL"/>
      </geometry>
    </collision>
  </link>
  <joint name="Joint3_2" type="revolute">
    <origin rpy="0 0 0" xyz="-0.027067201254057 -0.0398182322092834 -0.0184000000000006"/>
    <parent link="Link3_1"/>
    <child link="Link3_2"/>
    <axis xyz="0.499999999999997 -0.866025403784441 0"/>
    <limit effort="100" lower="-7" upper="7" velocity="100"/>
  </joint>
  <link name="Link3_3">
    <inertial>
      <origin rpy="0 0 0" xyz="-0.00448111379492015 0.0212609753086896 -0.0449869693344172"/>
      <mass value="0.2"/>
     <inertia ixx="5" ixy="0" ixz="0" iyy="5" iyz="0" izz="5"/>
    </inertial>
    <visual>
      <origin rpy="0 0 0" xyz="0 0 0"/>
      <geometry>
        <mesh filename="package://sc_description/meshes/Link3_3.STL"/>
      </geometry>
      <material name="">
        <color rgba="1 1 1 1"/>
      </material>
    </visual>
    <collision>
      <origin rpy="0 0 0" xyz="0 0 0"/>
      <geometry>
        <mesh filename="package://sc_description/meshes/Link3_3.STL"/>
        <friction>      
	    <ode>      
	       <mu>1.5</mu>
	       <mu2>1.5</mu2>
	    </ode>      
	  </friction>
      </geometry>
    </collision>
  </link>
  <joint name="Joint3_3" type="revolute">
    <origin rpy="0 0 0" xyz="-0.0497861313024051 -0.028744036309354 0.0399389722775643"/>
    <parent link="Link3_2"/>
    <child link="Link3_3"/>
    <axis xyz="0.499999999999995 -0.866025403784441 0"/>
    <limit effort="100" lower="-7" upper="7" velocity="100"/>
  </joint>
  <link name="Link4_1">
    <inertial>
      <origin rpy="0 0 0" xyz="0.0298023675057879 0.0180709386845208 -0.0182493773593328"/>
      <mass value="0.2"/>
      <inertia ixx="5" ixy="0" ixz="0" iyy="5" iyz="0" izz="5"/>
    </inertial>
    <visual>
      <origin rpy="0 0 0" xyz="0 0 0"/>
      <geometry>
        <mesh filename="package://sc_description/meshes/Link4_1.STL"/>
      </geometry>
      <material name="">
        <color rgba="1 1 1 1"/>
      </material>
    </visual>
    <collision>
      <origin rpy="0 0 0" xyz="0 0 0"/>
      <geometry>
        <mesh filename="package://sc_description/meshes/Link4_1.STL"/>
      </geometry>
    </collision>
  </link>
  <joint name="Joint4_1" type="revolute">
    <origin rpy="0 0 0" xyz="0.062392 0.061425 0.02595"/>
    <parent link="BASE"/>
    <child link="Link4_1"/>
    <axis xyz="0 0 1"/>
    <limit effort="100" lower="-7" upper="7" velocity="100"/>
  </joint>
  <link name="Link4_2">
    <inertial>
      <origin rpy="0 0 0" xyz="0.0339473022105704 -0.00131037958989749 0.0199694861387749"/>
      <mass value="0.2"/>
      <inertia ixx="5" ixy="0" ixz="0" iyy="5" iyz="0" izz="5"/>
    </inertial>
    <visual>
      <origin rpy="0 0 0" xyz="0 0 0"/>
      <geometry>
        <mesh filename="package://sc_description/meshes/Link4_2.STL"/>
      </geometry>
      <material name="">
        <color rgba="1 1 1 1"/>
      </material>
    </visual>
    <collision>
      <origin rpy="0 0 0" xyz="0 0 0"/>
      <geometry>
        <mesh filename="package://sc_description/meshes/Link4_2.STL"/>
      </geometry>
    </collision>
  </link>
  <joint name="Joint4_2" type="revolute">
    <origin rpy="0 0 0" xyz="0.0270672012540568 0.0398182322092834 -0.0184000000000009"/>
    <parent link="Link4_1"/>
    <child link="Link4_2"/>
    <axis xyz="-0.499999999999995 0.866025403784441 0"/>
    <limit effort="100" lower="-7" upper="7" velocity="100"/>
  </joint>
  <link name="Link4_3">
    <inertial>
      <origin rpy="0 0 0" xyz="0.00448111379584698 -0.0212609753047241 -0.0449869693216264"/>
      <mass value="0.2"/>
      <inertia ixx="5" ixy="0" ixz="0" iyy="5" iyz="0" izz="5"/>
    </inertial>
    <visual>
      <origin rpy="0 0 0" xyz="0 0 0"/>
      <geometry>
        <mesh filename="package://sc_description/meshes/Link4_3.STL"/>
      </geometry>
      <material name="">
        <color rgba="1 1 1 1"/>
      </material>
    </visual>
    <collision>
      <origin rpy="0 0 0" xyz="0 0 0"/>
      <geometry>
        <mesh filename="package://sc_description/meshes/Link4_3.STL"/>
        <friction>      
	    <ode>      
	       <mu>1.5</mu>
	       <mu2>1.5</mu2>
	    </ode>      
	  </friction>
      </geometry>
    </collision>
  </link>
  <joint name="Joint4_3" type="revolute">
    <origin rpy="0 0 0" xyz="0.0497861313024057 0.0287440363093538 0.0399389722775637"/>
    <parent link="Link4_2"/>
    <child link="Link4_3"/>
    <axis xyz="-0.499999999999994 0.866025403784442 0"/>
    <limit effort="100" lower="-7" upper="7" velocity="100"/>
  </joint>
  <link name="Link5_1">
    <inertial>
      <origin rpy="0 0 0" xyz="0.0348450751668918 0.000748713096014895 -0.0182493776997562"/>
      <mass value="0.2"/>
      <inertia ixx="5" ixy="0" ixz="0" iyy="5" iyz="0" izz="5"/>
    </inertial>
    <visual>
      <origin rpy="0 0 0" xyz="0 0 0"/>
      <geometry>
        <mesh filename="package://sc_description/meshes/Link5_1.STL"/>
      </geometry>
      <material name="">
        <color rgba="1 1 1 1"/>
      </material>
    </visual>
    <collision>
      <origin rpy="0 0 0" xyz="0 0 0"/>
      <geometry>
        <mesh filename="package://sc_description/meshes/Link5_1.STL"/>
      </geometry>
    </collision>
  </link>
  <joint name="Joint5_1" type="revolute">
    <origin rpy="0 0 0" xyz="0.082878 -0.0125 0.02595"/>
    <parent link="BASE"/>
    <child link="Link5_1"/>
    <axis xyz="0 0 1"/>
    <limit effort="100" lower="-7" upper="7" velocity="100"/>
  </joint>
  <link name="Link5_2">
    <inertial>
      <origin rpy="0 0 0" xyz="0.0287440363093529 -0.0181084731187368 0.0199694861387749"/>
      <mass value="0.27"/>
      <inertia ixx="5" ixy="0" ixz="0" iyy="5" iyz="0" izz="5"/>
    </inertial>
    <visual>
      <origin rpy="0 0 0" xyz="0 0 0"/>
      <geometry>
        <mesh filename="package://sc_description/meshes/Link5_2.STL"/>
      </geometry>
      <material name="">
        <color rgba="1 1 1 1"/>
      </material>
    </visual>
    <collision>
      <origin rpy="0 0 0" xyz="0 0 0"/>
      <geometry>
        <mesh filename="package://sc_description/meshes/Link5_2.STL"/>
      </geometry>
    </collision>
  </link>
  <joint name="Joint5_2" type="revolute">
    <origin rpy="0 0 0" xyz="0.0433500000000008 0.0209499999999989 -0.018400000000001"/>
    <parent link="Link5_1"/>
    <child link="Link5_2"/>
    <axis xyz="0 1 0"/>
    <limit effort="100" lower="-7" upper="7" velocity="100"/>
  </joint>
  <link name="Link5_3">
    <inertial>
      <origin rpy="0 0 0" xyz="-0.00674972943954649 -0.0206531015817771 -0.0449869694459858"/>
      <mass value="0.2"/>
      <inertia ixx="5" ixy="0" ixz="0" iyy="5" iyz="0" izz="5"/>
    </inertial>
    <visual>
      <origin rpy="0 0 0" xyz="0 0 0"/>
      <geometry>
        <mesh filename="package://sc_description/meshes/Link5_3.STL"/>
      </geometry>
      <material name="">
        <color rgba="1 1 1 1"/>
      </material>
    </visual>
    <collision>
      <origin rpy="0 0 0" xyz="0 0 0"/>
      <geometry>
        <mesh filename="package://sc_description/meshes/Link5_3.STL"/>
        <friction>      
	    <ode>      
	       <mu>1.5</mu>
	       <mu2>1.5</mu2>
	    </ode>      
	  </friction>
      </geometry>
    </collision>
  </link>
  <joint name="Joint5_3" type="revolute">
    <origin rpy="0 0 0" xyz="0.0574880726187079 0 0.0399389722775636"/>
    <parent link="Link5_2"/>
    <child link="Link5_3"/>
    <axis xyz="0 1 0"/>
    <limit effort="100" lower="-7" upper="7" velocity="100"/>
  </joint>
  <link name="Link6_1">
    <inertial>
      <origin rpy="0 0 0" xyz="0.0305510790668958 -0.0167741325777971 -0.0182493779392898"/>
      <mass value="0.2"/>
      <inertia ixx="5" ixy="0" ixz="0" iyy="5" iyz="0" izz="5"/>
    </inertial>
    <visual>
      <origin rpy="0 0 0" xyz="0 0 0"/>
      <geometry>
        <mesh filename="package://sc_description/meshes/Link6_1.STL"/>
      </geometry>
      <material name="">
        <color rgba="1 1 1 1"/>
      </material>
    </visual>
    <collision>
      <origin rpy="0 0 0" xyz="0 0 0"/>
      <geometry>
        <mesh filename="package://sc_description/meshes/Link6_1.STL"/>
      </geometry>
    </collision>
  </link>
  <joint name="Joint6_1" type="revolute">
    <origin rpy="0 0 0" xyz="0.062392 -0.086425 0.02595"/>
    <parent link="BASE"/>
    <child link="Link6_1"/>
    <axis xyz="0 0 1"/>
    <limit effort="100" lower="-7" upper="7" velocity="100"/>
  </joint>
  <link name="Link6_2">
    <inertial>
      <origin rpy="0 0 0" xyz="0.0158388290918338 -0.03005441589925 0.019969486138775"/>
      <mass value="0.2"/>
      <inertia ixx="5" ixy="0" ixz="0" iyy="5" iyz="0" izz="5"/>
    </inertial>
    <visual>
      <origin rpy="0 0 0" xyz="0 0 0"/>
      <geometry>
        <mesh filename="package://sc_description/meshes/Link6_2.STL"/>
      </geometry>
      <material name="">
        <color rgba="1 1 1 1"/>
      </material>
    </visual>
    <collision>
      <origin rpy="0 0 0" xyz="0 0 0"/>
      <geometry>
        <mesh filename="package://sc_description/meshes/Link6_2.STL"/>
      </geometry>
    </collision>
  </link>
  <joint name="Joint6_2" type="revolute">
    <origin rpy="0 0 0" xyz="0.0480172012540556 -0.00353176779071687 -0.0184000000000011"/>
    <parent link="Link6_1"/>
    <child link="Link6_2"/>
    <axis xyz="0.499999999999991 0.866025403784444 0"/>
    <limit effort="100" lower="-7" upper="7" velocity="100"/>
  </joint>
  <link name="Link6_3">
    <inertial>
      <origin rpy="0 0 0" xyz="-0.016171988032116 -0.0145112462987466 -0.0449869707656819"/>
      <mass value="0.2"/>
      <inertia ixx="5" ixy="0" ixz="0" iyy="5" iyz="0" izz="5"/>
    </inertial>
    <visual>
      <origin rpy="0 0 0" xyz="0 0 0"/>
      <geometry>
        <mesh filename="package://sc_description/meshes/Link6_3.STL"/>
      </geometry>
      <material name="">
        <color rgba="1 1 1 1"/>
      </material>
    </visual>
    <collision>
      <origin rpy="0 0 0" xyz="0 0 0"/>
      <geometry>
        <mesh filename="package://sc_description/meshes/Link6_3.STL"/>
        <friction>      
	    <ode>      
	       <mu>1.5</mu>
	       <mu2>1.5</mu2>
	    </ode>      
	  </friction>
      </geometry>
    </collision>
  </link>
  <joint name="Joint6_3" type="revolute">
    <origin rpy="0 0 0" xyz="0.0497861313024061 -0.0287440363093529 0.0399389722775637"/>
    <parent link="Link6_2"/>
    <child link="Link6_3"/>
    <axis xyz="0.499999999999993 0.866025403784443 0"/>
    <limit effort="100" lower="-7" upper="7" velocity="100"/>
  </joint>
  <link name="TLink1">
    <inertial>
      <origin rpy="0 0 0" xyz="0.000341212910543842 0.0183451092488032 0.0417109463245265"/>
      <mass value="0.3"/>
      <inertia ixx="5" ixy="0" ixz="0" iyy="5" iyz="0" izz="5"/>
    </inertial>
    <visual>
      <origin rpy="0 0 0" xyz="0 0 0"/>
      <geometry>
        <mesh filename="package://sc_description/meshes/TLink1.STL"/>
      </geometry>
      <material name="">
        <color rgba="1 1 1 1"/>
      </material>
    </visual>
    <collision>
      <origin rpy="0 0 0" xyz="0 0 0"/>
      <geometry>
        <mesh filename="package://sc_description/meshes/TLink1.STL"/>
      </geometry>
    </collision>
  </link>
  <joint name="TJoint1" type="revolute">
    <origin rpy="0 0 0" xyz="0 -0.10845 0.03265"/>
    <parent link="BASE"/>
    <child link="TLink1"/>
    <axis xyz="0 -1 0"/>
    <limit effort="100" lower="-7" upper="7" velocity="100"/>
  </joint>
  <link name="TLink2">
    <inertial>
      <origin rpy="0 0 0" xyz="-0.00228905348926284 7.27198856687039E-12 0.0257970095548198"/>
      <mass value="0.0168370698582301"/>
      <inertia ixx="5" ixy="0" ixz="0" iyy="5" iyz="0" izz="5"/>
    </inertial>
    <visual>
      <origin rpy="0 0 0" xyz="0 0 0"/>
      <geometry>
        <mesh filename="package://sc_description/meshes/TLink2.STL"/>
      </geometry>
      <material name="">
        <color rgba="1 1 1 1"/>
      </material>
    </visual>
    <collision>
      <origin rpy="0 0 0" xyz="0 0 0"/>
      <geometry>
        <mesh filename="package://sc_description/meshes/TLink2.STL"/>
      </geometry>
    </collision>
  </link>
  <joint name="TJoint2" type="revolute">
    <origin rpy="0 0 0" xyz="0.000638050844598892 0.0184 0.0779973902840326"/>
    <parent link="TLink1"/>
    <child link="TLink2"/>
    <axis xyz="0.999966542102983 0 -0.00818013903322798"/>
    <limit effort="100" lower="-7" upper="7" velocity="100"/>
  </joint>
  <link name="TLink3">
    <inertial>
      <origin rpy="0 0 0" xyz="0.000210862865994615 7.27194693350697E-12 0.0257765592072368"/>
      <mass value="0.0168370698582301"/>
      <inertia ixx="5" ixy="0" ixz="0" iyy="5" iyz="0" izz="5"/>
    </inertial>
    <visual>
      <origin rpy="0 0 0" xyz="0 0 0"/>
      <geometry>
        <mesh filename="package://sc_description/meshes/TLink3.STL"/>
      </geometry>
      <material name="">
        <color rgba="1 1 1 1"/>
      </material>
    </visual>
    <collision>
      <origin rpy="0 0 0" xyz="0 0 0"/>
      <geometry>
        <mesh filename="package://sc_description/meshes/TLink3.STL"/>
      </geometry>
    </collision>
  </link>
  <joint name="TJoint3" type="revolute">
    <origin rpy="0 0 0" xyz="-0.0021113597511791 0 0.0475188610974747"/>
    <parent link="TLink2"/>
    <child link="TLink3"/>
    <axis xyz="0.999966542102983 0 -0.00818013903322868"/>
    <limit effort="100" lower="-7" upper="7" velocity="100"/>
  </joint>
  <link name="TLink4">
    <inertial>
      <origin rpy="0 0 0" xyz="4.80741628913761E-05 8.36712022861397E-08 0.028187031288893"/>
      <mass value="0.0194049472630492"/>
      <inertia ixx="5" ixy="0" ixz="0" iyy="5" iyz="0" izz="5"/>
    </inertial>
    <visual>
      <origin rpy="0 0 0" xyz="0 0 0"/>
      <geometry>
        <mesh filename="package://sc_description/meshes/TLink4.STL"/>
      </geometry>
      <material name="">
        <color rgba="1 1 1 1"/>
      </material>
    </visual>
    <collision>
      <origin rpy="0 0 0" xyz="0 0 0"/>
      <geometry>
        <mesh filename="package://sc_description/meshes/TLink4.STL"/>
      </geometry>
    </collision>
  </link>
  <joint name="TJoint4" type="revolute">
    <origin rpy="0 0 0" xyz="0.000388556604078327 0 0.0474984107498917"/>
    <parent link="TLink3"/>
    <child link="TLink4"/>
    <axis xyz="-0.999966542102983 0 0.00818013903322775"/>
    <limit effort="100" lower="-7" upper="7" velocity="100"/>
  </joint>
  <link name="TLink5">
    <inertial>
      <origin rpy="0 0 0" xyz="0.00187420750278167 -2.91089623793983E-08 0.0155490679961494"/>
      <mass value="0.0326658696380878"/>
      <inertia ixx="5" ixy="0" ixz="0" iyy="5" iyz="0" izz="5"/>
    </inertial>
    <visual>
      <origin rpy="0 0 0" xyz="0 0 0"/>
      <geometry>
        <mesh filename="package://sc_description/meshes/TLink5.STL"/>
      </geometry>
      <material name="">
        <color rgba="1 1 1 1"/>
      </material>
    </visual>
    <collision>
      <origin rpy="0 0 0" xyz="0 0 0"/>
      <geometry>
        <mesh filename="package://sc_description/meshes/TLink5.STL"/>
      </geometry>
    </collision>
  </link>
  <joint name="TJoint5" type="revolute">
    <origin rpy="0 0 0" xyz="-0.00471259926050435 0 0.0534903393914256"/>
    <parent link="TLink4"/>
    <child link="TLink5"/>
    <axis xyz="0.00818013903322799 0 0.999966542102983"/>
    <limit effort="100" lower="-7" upper="7" velocity="100"/>
  </joint>
  <link name="TLink5_1">
    <inertial>
      <origin rpy="0 0 0" xyz="7.21116032783575E-05 -0.00139253498058628 0.00882045616801402"/>
      <mass value="0.00289407866796548"/>
      <inertia ixx="5" ixy="0" ixz="0" iyy="5" iyz="0" izz="5"/>
    </inertial>
    <visual>
      <origin rpy="0 0 0" xyz="0 0 0"/>
      <geometry>
        <mesh filename="package://sc_description/meshes/TLink5_1.STL"/>
      </geometry>
      <material name="">
        <color rgba="1 1 1 1"/>
      </material>
    </visual>
    <collision>
      <origin rpy="0 0 0" xyz="0 0 0"/>
      <geometry>
        <mesh filename="package://sc_description/meshes/TLink5_1.STL"/>
      </geometry>
    </collision>
  </link>
  <joint name="TJoint5_1" type="revolute">
    <origin rpy="0 0 0" xyz="0.00550239168416253 0.017 0.0430564302486174"/>
    <parent link="TLink5"/>
    <child link="TLink5_1"/>
    <axis xyz="0.999966542102983 0 -0.00818013903322775"/>
    <limit effort="100" lower="-7" upper="7" velocity="100"/>
  </joint>
  <link name="TLink5_2">
    <inertial>
      <origin rpy="0 0 0" xyz="7.29067167685171E-05 0.00117680154680974 0.00891765231377004"/>
      <mass value="0.00289407865197651"/>
     <inertia ixx="5" ixy="0" ixz="0" iyy="5" iyz="0" izz="5"/>
    </inertial>
    <visual>
      <origin rpy="0 0 0" xyz="0 0 0"/>
      <geometry>
        <mesh filename="package://sc_description/meshes/TLink5_2.STL"/>
      </geometry>
      <material name="">
        <color rgba="1 1 1 1"/>
      </material>
    </visual>
    <collision>
      <origin rpy="0 0 0" xyz="0 0 0"/>
      <geometry>
        <mesh filename="package://sc_description/meshes/TLink5_2.STL"/>
      </geometry>
    </collision>
  </link>
  <joint name="TJoint5_2" type="revolute">
    <origin rpy="0 0 0" xyz="0.00550239168416244 -0.017 0.0430564302486175"/>
    <parent link="TLink5"/>
    <child link="TLink5_2"/>
    <axis xyz="0.999966542102983 0 -0.00818013903322775"/>
    <limit effort="100" lower="-7" upper="7" velocity="100"/>
  </joint>
  <link name="LLink1">
    <inertial>
      <origin rpy="0 0 0" xyz="-0.000298924163147307 0.0265937423803867 -0.00191385785280266"/>
      <mass value="0.0115574626542669"/>
      <inertia ixx="5" ixy="0" ixz="0" iyy="5" iyz="0" izz="5"/>
    </inertial>
    <visual>
      <origin rpy="0 0 0" xyz="0 0 0"/>
      <geometry>
        <mesh filename="package://sc_description/meshes/LLink1.STL"/>
      </geometry>
      <material name="">
        <color rgba="1 1 1 1"/>
      </material>
    </visual>
    <collision>
      <origin rpy="0 0 0" xyz="0 0 0"/>
      <geometry>
        <mesh filename="package://sc_description/meshes/LLink1.STL"/>
      </geometry>
    </collision>
  </link>
  <joint name="LJoint1" type="revolute">
    <origin rpy="0 0 0" xyz="-0.08185 0.09975 0.08595"/>
    <parent link="BASE"/>
    <child link="LLink1"/>
    <axis xyz="0 0 1"/>
    <limit effort="100" lower="-7" upper="7" velocity="100"/>
  </joint>
  <link name="LLink2">
    <inertial>
      <origin rpy="0 0 0" xyz="0.0205496139288378 0.0175021550443651 0.000234379053507143"/>
      <mass value="0.0340893649012877"/>
      <inertia ixx="5" ixy="0" ixz="0" iyy="5" iyz="0" izz="5"/>
    </inertial>
    <visual>
      <origin rpy="0 0 0" xyz="0 0 0"/>
      <geometry>
        <mesh filename="package://sc_description/meshes/LLink2.STL"/>
      </geometry>
      <material name="">
        <color rgba="1 1 1 1"/>
      </material>
    </visual>
    <collision>
      <origin rpy="0 0 0" xyz="0 0 0"/>
      <geometry>
        <mesh filename="package://sc_description/meshes/LLink2.STL"/>
      </geometry>
    </collision>
  </link>
  <joint name="LJoint2" type="revolute">
    <origin rpy="0 0 0" xyz="-0.0184000000000004 0.0500000000000003 -0.0019000000000001"/>
    <parent link="LLink1"/>
    <child link="LLink2"/>
    <axis xyz="-1 0 0"/>
    <limit effort="100" lower="-7" upper="7" velocity="100"/>
  </joint>
  <link name="LLink3">
    <inertial>
      <origin rpy="0 0 0" xyz="-0.00174695120635276 0.0155624857969087 0.000208289726052968"/>
      <mass value="0.0326658685720031"/>
      <inertia ixx="5" ixy="0" ixz="0" iyy="5" iyz="0" izz="5"/>
    </inertial>
    <visual>
      <origin rpy="0 0 0" xyz="0 0 0"/>
      <geometry>
        <mesh filename="package://sc_description/meshes/LLink3.STL"/>
      </geometry>
      <material name="">
        <color rgba="1 1 1 1"/>
      </material>
    </visual>
    <collision>
      <origin rpy="0 0 0" xyz="0 0 0"/>
      <geometry>
        <mesh filename="package://sc_description/meshes/LLink3.STL"/>
      </geometry>
    </collision>
  </link>
  <joint name="LJoint3" type="revolute">
    <origin rpy="0 0 0" xyz="0.0261 0.058294777461831 0.00078033369499371"/>
    <parent link="LLink2"/>
    <child link="LLink3"/>
    <axis xyz="0 0.999910419585446 0.0133847975127525"/>
    <limit effort="100" lower="-7" upper="7" velocity="100"/>
  </joint>
  <link name="LLink3_1">
    <inertial>
      <origin rpy="0 0 0" xyz="4.3367715751863E-08 0.00890140013993151 0.00129606105888094"/>
      <mass value="0.00289407866969813"/>
      <inertia ixx="5" ixy="0" ixz="0" iyy="5" iyz="0" izz="5"/>
    </inertial>
    <visual>
      <origin rpy="0 0 0" xyz="0 0 0"/>
      <geometry>
        <mesh filename="package://sc_description/meshes/LLink3_1.STL"/>
      </geometry>
      <material name="">
        <color rgba="1 1 1 1"/>
      </material>
    </visual>
    <collision>
      <origin rpy="0 0 0" xyz="0 0 0"/>
      <geometry>
        <mesh filename="package://sc_description/meshes/LLink3_1.STL"/>
      </geometry>
    </collision>
  </link>
  <joint name="LJoint3_1" type="revolute">
    <origin rpy="0 0 0" xyz="-0.0051500000000001 0.0433236806418495 -0.0164215923601529"/>
    <parent link="LLink3"/>
    <child link="LLink3_1"/>
    <axis xyz="-1 0 0"/>
    <limit effort="100" lower="-7" upper="7" velocity="100"/>
  </joint>
  <link name="LLink3_2">
    <inertial>
      <origin rpy="0 0 0" xyz="4.33588432102727E-08 0.00883859954810817 -0.00127434628893146"/>
      <mass value="0.00289407865390281"/>
      <inertia ixx="5" ixy="0" ixz="0" iyy="5" iyz="0" izz="5"/>
    </inertial>
    <visual>
      <origin rpy="0 0 0" xyz="0 0 0"/>
      <geometry>
        <mesh filename="package://sc_description/meshes/LLink3_2.STL"/>
      </geometry>
      <material name="">
        <color rgba="1 1 1 1"/>
      </material>
    </visual>
    <collision>
      <origin rpy="0 0 0" xyz="0 0 0"/>
      <geometry>
        <mesh filename="package://sc_description/meshes/LLink3_2.STL"/>
      </geometry>
    </collision>
  </link>
  <joint name="LJoint3_2" type="revolute">
    <origin rpy="0 0 0" xyz="-0.00514999999999999 0.0428685975264159 0.0175753619057523"/>
    <parent link="LLink3"/>
    <child link="LLink3_2"/>
    <axis xyz="-1 0 0"/>
    <limit effort="100" lower="-7" upper="7" velocity="100"/>
  </joint>
  <link name="RLink1">
    <inertial>
      <origin rpy="0 0 0" xyz="-0.000298924163147085 0.0265937423803867 -0.00191385785280264"/>
      <mass value="0.0115574626542669"/>
      <inertia ixx="5" ixy="0" ixz="0" iyy="5" iyz="0" izz="5"/>
    </inertial>
    <visual>
      <origin rpy="0 0 0" xyz="0 0 0"/>
      <geometry>
        <mesh filename="package://sc_description/meshes/RLink1.STL"/>
      </geometry>
      <material name="">
        <color rgba="1 1 1 1"/>
      </material>
    </visual>
    <collision>
      <origin rpy="0 0 0" xyz="0 0 0"/>
      <geometry>
        <mesh filename="package://sc_description/meshes/RLink1.STL"/>
      </geometry>
    </collision>
  </link>
  <joint name="RJoint1" type="revolute">
    <origin rpy="0 0 0" xyz="0.0818500000000012 0.0997499999999982 0.0859499999999994"/>
    <parent link="BASE"/>
    <child link="RLink1"/>
    <axis xyz="0 0 1"/>
    <limit effort="100" lower="-7" upper="7" velocity="100"/>
  </joint>
  <link name="RLink2">
    <inertial>
      <origin rpy="0 0 0" xyz="0.0205496139372623 0.0175021550440243 0.000234379054560946"/>
      <mass value="0.0340893648716292"/>
      <inertia ixx="5" ixy="0" ixz="0" iyy="5" iyz="0" izz="5"/>
    </inertial>
    <visual>
      <origin rpy="0 0 0" xyz="0 0 0"/>
      <geometry>
        <mesh filename="package://sc_description/meshes/RLink2.STL"/>
      </geometry>
      <material name="">
        <color rgba="1 1 1 1"/>
      </material>
    </visual>
    <collision>
      <origin rpy="0 0 0" xyz="0 0 0"/>
      <geometry>
        <mesh filename="package://sc_description/meshes/RLink2.STL"/>
      </geometry>
    </collision>
  </link>
  <joint name="RJoint2" type="revolute">
    <origin rpy="0 0 0" xyz="-0.0183999999999999 0.0500000000000004 -0.00190000000000004"/>
    <parent link="RLink1"/>
    <child link="RLink2"/>
    <axis xyz="-1 0 0"/>
    <limit effort="100" lower="-7" upper="7" velocity="100"/>
  </joint>
  <link name="RLink3">
    <inertial>
      <origin rpy="0 0 0" xyz="-0.00176276782605905 0.0157134798716438 0.000210310666534673"/>
      <mass value="0.0323727705454218"/>
      <inertia ixx="5" ixy="0" ixz="0" iyy="5" iyz="0" izz="5"/>
    </inertial>
    <visual>
      <origin rpy="0 0 0" xyz="0 0 0"/>
      <geometry>
        <mesh filename="package://sc_description/meshes/RLink3.STL"/>
      </geometry>
      <material name="">
        <color rgba="1 1 1 1"/>
      </material>
    </visual>
    <collision>
      <origin rpy="0 0 0" xyz="0 0 0"/>
      <geometry>
        <mesh filename="package://sc_description/meshes/RLink3.STL"/>
      </geometry>
    </collision>
  </link>
  <joint name="RJoint3" type="revolute">
    <origin rpy="0 0 0" xyz="0.0261000000000005 0.0582947774618308 0.000780333694993751"/>
    <parent link="RLink2"/>
    <child link="RLink3"/>
    <axis xyz="0 0.999910419585446 0.0133847975127534"/>
    <limit effort="100" lower="-7" upper="7" velocity="100"/>
  </joint>
  <link name="RLink3_1">
    <inertial>
      <origin rpy="0 0 0" xyz="4.33632795782124E-08 0.00890140016805663 0.00129606107897806"/>
      <mass value="0.00289407866180048"/>
      <inertia ixx="5" ixy="0" ixz="0" iyy="5" iyz="0" izz="5"/>
    </inertial>
    <visual>
      <origin rpy="0 0 0" xyz="0 0 0"/>
      <geometry>
        <mesh filename="package://sc_description/meshes/RLink3_1.STL"/>
      </geometry>
      <material name="">
        <color rgba="1 1 1 1"/>
      </material>
    </visual>
    <collision>
      <origin rpy="0 0 0" xyz="0 0 0"/>
      <geometry>
        <mesh filename="package://sc_description/meshes/RLink3_1.STL"/>
      </geometry>
    </collision>
  </link>
  <joint name="RJoint3_1" type="revolute">
    <origin rpy="0 0 0" xyz="-0.00514999999999965 0.0433236806418496 -0.0164215923601529"/>
    <parent link="RLink3"/>
    <child link="RLink3_1"/>
    <axis xyz="-1 0 0"/>
    <limit effort="100" lower="-7" upper="7" velocity="100"/>
  </joint>
  <link name="RLink3_2">
    <inertial>
      <origin rpy="0 0 0" xyz="4.33544071198888E-08 0.00883859958734828 -0.00127434629217303"/>
      <mass value="0.00289407864600513"/>
      <inertia ixx="5" ixy="0" ixz="0" iyy="5" iyz="0" izz="5"/>
    </inertial>
    <visual>
      <origin rpy="0 0 0" xyz="0 0 0"/>
      <geometry>
        <mesh filename="package://sc_description/meshes/RLink3_2.STL"/>
      </geometry>
      <material name="">
        <color rgba="1 1 1 1"/>
      </material>
    </visual>
    <collision>
      <origin rpy="0 0 0" xyz="0 0 0"/>
      <geometry>
        <mesh filename="package://sc_description/meshes/RLink3_2.STL"/>
      </geometry>
    </collision>
  </link>
  <joint name="RJoint3_2" type="revolute">
    <origin rpy="0 0 0" xyz="-0.00514999999999954 0.0428685975264159 0.0175753619057523"/>
    <parent link="RLink3"/>
    <child link="RLink3_2"/>
    <axis xyz="-1 0 0"/>
    <limit effort="100" lower="-7" upper="7" velocity="100"/>
  </joint>
   <transmission name="trans_Joint1_1">
        <type>transmission_interface/SimpleTransmission</type>
        <joint name="Joint1_1">
            <hardwareInterface>hardware_interface/EffortJointInterface</hardwareInterface>
        </joint>
        <actuator name="Joint1_1_motor">
            <hardwareInterface>hardware_interface/EffortJointInterface</hardwareInterface>
            <mechanicalReduction>1</mechanicalReduction>
        </actuator>
    </transmission>
    <transmission name="trans_Joint1_2">
        <type>transmission_interface/SimpleTransmission</type>
        <joint name="Joint1_2">
            <hardwareInterface>hardware_interface/EffortJointInterface</hardwareInterface>
        </joint>
        <actuator name="Joint1_2_motor">
            <hardwareInterface>hardware_interface/EffortJointInterface</hardwareInterface>
            <mechanicalReduction>1</mechanicalReduction>
        </actuator>
    </transmission>
    <transmission name="trans_Joint1_3">
        <type>transmission_interface/SimpleTransmission</type>
        <joint name="Joint1_3">
            <hardwareInterface>hardware_interface/EffortJointInterface</hardwareInterface>
        </joint>
        <actuator name="Joint1_3_motor">
            <hardwareInterface>hardware_interface/EffortJointInterface</hardwareInterface>
            <mechanicalReduction>1</mechanicalReduction>
        </actuator>
    </transmission>
    <transmission name="trans_Joint2_1">
        <type>transmission_interface/SimpleTransmission</type>
        <joint name="Joint2_1">
            <hardwareInterface>hardware_interface/EffortJointInterface</hardwareInterface>
        </joint>
        <actuator name="Joint2_1_motor">
            <hardwareInterface>hardware_interface/EffortJointInterface</hardwareInterface>
            <mechanicalReduction>1</mechanicalReduction>
        </actuator>
    </transmission>
    <transmission name="trans_Joint2_2">
        <type>transmission_interface/SimpleTransmission</type>
        <joint name="Joint2_2">
            <hardwareInterface>hardware_interface/EffortJointInterface</hardwareInterface>
        </joint>
        <actuator name="Joint2_2_motor">
            <hardwareInterface>hardware_interface/EffortJointInterface</hardwareInterface>
            <mechanicalReduction>1</mechanicalReduction>
        </actuator>
    </transmission>
    <transmission name="trans_Joint2_3">
        <type>transmission_interface/SimpleTransmission</type>
        <joint name="Joint2_3">
            <hardwareInterface>hardware_interface/EffortJointInterface</hardwareInterface>
        </joint>
        <actuator name="Joint2_3_motor">
            <hardwareInterface>hardware_interface/EffortJointInterface</hardwareInterface>
            <mechanicalReduction>1</mechanicalReduction>
        </actuator>
    </transmission>
    <transmission name="trans_Joint3_1">
        <type>transmission_interface/SimpleTransmission</type>
        <joint name="Joint3_1">
            <hardwareInterface>hardware_interface/EffortJointInterface</hardwareInterface>
        </joint>
        <actuator name="Joint3_1_motor">
            <hardwareInterface>hardware_interface/EffortJointInterface</hardwareInterface>
            <mechanicalReduction>1</mechanicalReduction>
        </actuator>
    </transmission>
    <transmission name="trans_Joint3_2">
        <type>transmission_interface/SimpleTransmission</type>
        <joint name="Joint3_2">
            <hardwareInterface>hardware_interface/EffortJointInterface</hardwareInterface>
        </joint>
        <actuator name="Joint3_2_motor">
            <hardwareInterface>hardware_interface/EffortJointInterface</hardwareInterface>
            <mechanicalReduction>1</mechanicalReduction>
        </actuator>
    </transmission>
    <transmission name="trans_Joint3_3">
        <type>transmission_interface/SimpleTransmission</type>
        <joint name="Joint3_3">
            <hardwareInterface>hardware_interface/EffortJointInterface</hardwareInterface>
        </joint>
        <actuator name="Joint3_3_motor">
            <hardwareInterface>hardware_interface/EffortJointInterface</hardwareInterface>
            <mechanicalReduction>1</mechanicalReduction>
        </actuator>
    </transmission>
    <transmission name="trans_Joint4_1">
        <type>transmission_interface/SimpleTransmission</type>
        <joint name="Joint4_1">
            <hardwareInterface>hardware_interface/EffortJointInterface</hardwareInterface>
        </joint>
        <actuator name="Joint4_1_motor">
            <hardwareInterface>hardware_interface/EffortJointInterface</hardwareInterface>
            <mechanicalReduction>1</mechanicalReduction>
        </actuator>
    </transmission>
    <transmission name="trans_Joint4_2">
        <type>transmission_interface/SimpleTransmission</type>
        <joint name="Joint4_2">
            <hardwareInterface>hardware_interface/EffortJointInterface</hardwareInterface>
        </joint>
        <actuator name="Joint4_2_motor">
            <hardwareInterface>hardware_interface/EffortJointInterface</hardwareInterface>
            <mechanicalReduction>1</mechanicalReduction>
        </actuator>
    </transmission>
    <transmission name="trans_Joint4_3">
        <type>transmission_interface/SimpleTransmission</type>
        <joint name="Joint4_3">
            <hardwareInterface>hardware_interface/EffortJointInterface</hardwareInterface>
        </joint>
        <actuator name="Joint4_3_motor">
            <hardwareInterface>hardware_interface/EffortJointInterface</hardwareInterface>
            <mechanicalReduction>1</mechanicalReduction>
        </actuator>
    </transmission>
    <transmission name="trans_Joint5_1">
        <type>transmission_interface/SimpleTransmission</type>
        <joint name="Joint5_1">
            <hardwareInterface>hardware_interface/EffortJointInterface</hardwareInterface>
        </joint>
        <actuator name="Joint5_1_motor">
            <hardwareInterface>hardware_interface/EffortJointInterface</hardwareInterface>
            <mechanicalReduction>1</mechanicalReduction>
        </actuator>
    </transmission>
    <transmission name="trans_Joint5_2">
        <type>transmission_interface/SimpleTransmission</type>
        <joint name="Joint5_2">
            <hardwareInterface>hardware_interface/EffortJointInterface</hardwareInterface>
        </joint>
        <actuator name="Joint5_2_motor">
            <hardwareInterface>hardware_interface/EffortJointInterface</hardwareInterface>
            <mechanicalReduction>1</mechanicalReduction>
        </actuator>
    </transmission>
    <transmission name="trans_Joint5_3">
        <type>transmission_interface/SimpleTransmission</type>
        <joint name="Joint5_3">
            <hardwareInterface>hardware_interface/EffortJointInterface</hardwareInterface>
        </joint>
        <actuator name="Joint5_3_motor">
            <hardwareInterface>hardware_interface/EffortJointInterface</hardwareInterface>
            <mechanicalReduction>1</mechanicalReduction>
        </actuator>
    </transmission>
    <transmission name="trans_Joint6_1">
        <type>transmission_interface/SimpleTransmission</type>
        <joint name="Joint6_1">
            <hardwareInterface>hardware_interface/EffortJointInterface</hardwareInterface>
        </joint>
        <actuator name="Joint6_1_motor">
            <hardwareInterface>hardware_interface/EffortJointInterface</hardwareInterface>
            <mechanicalReduction>1</mechanicalReduction>
        </actuator>
    </transmission>
    <transmission name="trans_Joint6_2">
        <type>transmission_interface/SimpleTransmission</type>
        <joint name="Joint6_2">
            <hardwareInterface>hardware_interface/EffortJointInterface</hardwareInterface>
        </joint>
        <actuator name="Joint6_2_motor">
            <hardwareInterface>hardware_interface/EffortJointInterface</hardwareInterface>
            <mechanicalReduction>1</mechanicalReduction>
        </actuator>
    </transmission>
    <transmission name="trans_Joint6_3">
        <type>transmission_interface/SimpleTransmission</type>
        <joint name="Joint6_3">
            <hardwareInterface>hardware_interface/EffortJointInterface</hardwareInterface>
        </joint>
        <actuator name="Joint6_3_motor">
            <hardwareInterface>hardware_interface/EffortJointInterface</hardwareInterface>
            <mechanicalReduction>1</mechanicalReduction>
        </actuator>
    </transmission>
    <transmission name="trans_TJoint1">
        <type>transmission_interface/SimpleTransmission</type>
        <joint name="TJoint1">
            <hardwareInterface>hardware_interface/EffortJointInterface</hardwareInterface>
        </joint>
        <actuator name="TJoint1_motor">
            <hardwareInterface>hardware_interface/EffortJointInterface</hardwareInterface>
            <mechanicalReduction>1</mechanicalReduction>
        </actuator>
    </transmission>
    <transmission name="trans_TJoint2">
        <type>transmission_interface/SimpleTransmission</type>
        <joint name="TJoint2">
            <hardwareInterface>hardware_interface/EffortJointInterface</hardwareInterface>
        </joint>
        <actuator name="TJoint2_motor">
            <hardwareInterface>hardware_interface/EffortJointInterface</hardwareInterface>
            <mechanicalReduction>1</mechanicalReduction>
        </actuator>
    </transmission>
    <transmission name="trans_TJoint3">
        <type>transmission_interface/SimpleTransmission</type>
        <joint name="TJoint3">
            <hardwareInterface>hardware_interface/EffortJointInterface</hardwareInterface>
        </joint>
        <actuator name="TJoint3_motor">
            <hardwareInterface>hardware_interface/EffortJointInterface</hardwareInterface>
            <mechanicalReduction>1</mechanicalReduction>
        </actuator>
    </transmission>
    <transmission name="trans_TJoint4">
        <type>transmission_interface/SimpleTransmission</type>
        <joint name="TJoint4">
            <hardwareInterface>hardware_interface/EffortJointInterface</hardwareInterface>
        </joint>
        <actuator name="TJoint4_motor">
            <hardwareInterface>hardware_interface/EffortJointInterface</hardwareInterface>
            <mechanicalReduction>1</mechanicalReduction>
        </actuator>
    </transmission>
    <transmission name="trans_TJoint5">
        <type>transmission_interface/SimpleTransmission</type>
        <joint name="TJoint5">
            <hardwareInterface>hardware_interface/EffortJointInterface</hardwareInterface>
        </joint>
        <actuator name="TJoint5_motor">
            <hardwareInterface>hardware_interface/EffortJointInterface</hardwareInterface>
            <mechanicalReduction>1</mechanicalReduction>
        </actuator>
    </transmission>
    <transmission name="trans_TJoint5_1">
        <type>transmission_interface/SimpleTransmission</type>
        <joint name="TJoint5_1">
            <hardwareInterface>hardware_interface/EffortJointInterface</hardwareInterface>
        </joint>
        <actuator name="TJoint5_1_motor">
            <hardwareInterface>hardware_interface/EffortJointInterface</hardwareInterface>
            <mechanicalReduction>1</mechanicalReduction>
        </actuator>
    </transmission>
    <transmission name="trans_TJoint5_2">
        <type>transmission_interface/SimpleTransmission</type>
        <joint name="TJoint5_2">
            <hardwareInterface>hardware_interface/EffortJointInterface</hardwareInterface>
        </joint>
        <actuator name="TJoint5_2_motor">
            <hardwareInterface>hardware_interface/EffortJointInterface</hardwareInterface>
            <mechanicalReduction>1</mechanicalReduction>
        </actuator>
    </transmission>
    <transmission name="trans_LJoint1">
        <type>transmission_interface/SimpleTransmission</type>
        <joint name="LJoint1">
            <hardwareInterface>hardware_interface/EffortJointInterface</hardwareInterface>
        </joint>
        <actuator name="LJoint1_motor">
            <hardwareInterface>hardware_interface/EffortJointInterface</hardwareInterface>
            <mechanicalReduction>1</mechanicalReduction>
        </actuator>
    </transmission>
    <transmission name="trans_LJoint2">
        <type>transmission_interface/SimpleTransmission</type>
        <joint name="LJoint2">
            <hardwareInterface>hardware_interface/EffortJointInterface</hardwareInterface>
        </joint>
        <actuator name="LJoint2_motor">
            <hardwareInterface>hardware_interface/EffortJointInterface</hardwareInterface>
            <mechanicalReduction>1</mechanicalReduction>
        </actuator>
    </transmission>
    <transmission name="trans_LJoint3">
        <type>transmission_interface/SimpleTransmission</type>
        <joint name="LJoint3">
            <hardwareInterface>hardware_interface/EffortJointInterface</hardwareInterface>
        </joint>
        <actuator name="LJoint3_motor">
            <hardwareInterface>hardware_interface/EffortJointInterface</hardwareInterface>
            <mechanicalReduction>1</mechanicalReduction>
        </actuator>
    </transmission>
    <transmission name="trans_LJoint3_1">
        <type>transmission_interface/SimpleTransmission</type>
        <joint name="LJoint3_1">
            <hardwareInterface>hardware_interface/EffortJointInterface</hardwareInterface>
        </joint>
        <actuator name="LJoint3_1_motor">
            <hardwareInterface>hardware_interface/EffortJointInterface</hardwareInterface>
            <mechanicalReduction>1</mechanicalReduction>
        </actuator>
    </transmission>
    <transmission name="trans_LJoint3_2">
        <type>transmission_interface/SimpleTransmission</type>
        <joint name="LJoint3_2">
            <hardwareInterface>hardware_interface/EffortJointInterface</hardwareInterface>
        </joint>
        <actuator name="LJoint3_2_motor">
            <hardwareInterface>hardware_interface/EffortJointInterface</hardwareInterface>
            <mechanicalReduction>1</mechanicalReduction>
        </actuator>
    </transmission>
    <transmission name="trans_RJoint1">
        <type>transmission_interface/SimpleTransmission</type>
        <joint name="RJoint1">
            <hardwareInterface>hardware_interface/EffortJointInterface</hardwareInterface>
        </joint>
        <actuator name="RJoint1_motor">
            <hardwareInterface>hardware_interface/EffortJointInterface</hardwareInterface>
            <mechanicalReduction>1</mechanicalReduction>
        </actuator>
    </transmission>
    <transmission name="trans_RJoint2">
        <type>transmission_interface/SimpleTransmission</type>
        <joint name="RJoint2">
            <hardwareInterface>hardware_interface/EffortJointInterface</hardwareInterface>
        </joint>
        <actuator name="RJoint2_motor">
            <hardwareInterface>hardware_interface/EffortJointInterface</hardwareInterface>
            <mechanicalReduction>1</mechanicalReduction>
        </actuator>
    </transmission>
    <transmission name="trans_RJoint3">
        <type>transmission_interface/SimpleTransmission</type>
        <joint name="RJoint3">
            <hardwareInterface>hardware_interface/EffortJointInterface</hardwareInterface>
        </joint>
        <actuator name="RJoint3_motor">
            <hardwareInterface>hardware_interface/EffortJointInterface</hardwareInterface>
            <mechanicalReduction>1</mechanicalReduction>
        </actuator>
    </transmission>
    <transmission name="trans_RJoint3_1">
        <type>transmission_interface/SimpleTransmission</type>
        <joint name="RJoint3_1">
            <hardwareInterface>hardware_interface/EffortJointInterface</hardwareInterface>
        </joint>
        <actuator name="RJoint3_1_motor">
            <hardwareInterface>hardware_interface/EffortJointInterface</hardwareInterface>
            <mechanicalReduction>1</mechanicalReduction>
        </actuator>
    </transmission>
    <transmission name="trans_RJoint3_2">
        <type>transmission_interface/SimpleTransmission</type>
        <joint name="RJoint3_2">
            <hardwareInterface>hardware_interface/EffortJointInterface</hardwareInterface>
        </joint>
        <actuator name="RJoint3_2_motor">
            <hardwareInterface>hardware_interface/EffortJointInterface</hardwareInterface>
            <mechanicalReduction>1</mechanicalReduction>
        </actuator>
    </transmission>
    <gazebo>
    <plugin filename="libgazebo_ros_control.so" name="gazebo_ros_control">
      <robotNamespace>/sc</robotNamespace>
    </plugin>
  </gazebo>
</robot>

